Workbook

Sheet Summary
A1: NET WORTH CERTIFICATE
A3: We hereby certify below the position of Assets & Liabilities of the person mentioned hereunder as on
A4: The same has been verified from the records & other details produced before us:
A5: Name
A6: PAN
A7: Date of Birth
A8: Permanent Address :
A9: Office Address
A11: (A) Total Value of Immoveable Property: (Annexure -1)
A12: (This includes beneficial share owned in Land, Building, Flat, Factory, Shop, House etc.)
A14: Nature of Property | B14: Location with Complete Address | D14: Value at Cost ( ` In Lacs)
A15: By Self | B15: Refer Annexure - 1 | D15: ='Annexure-1 Immovable Property'!H8 -> 0
A16: By Sharing | D16: ='Annexure-1 Immovable Property'!H12 -> 0
A18: TOTAL (A) | D18: =D15+D16 -> 0
A20: (B) Total Value of Other Assets:
A21: (This includes Cash, Bank balance, Gold, Other Jewellery, Investment in Shares/Mutual Funds/FD’s/LIC etc, Vehicles, Capital in Business etc.)
A23: Nature of Asset | B23: Particulars of Asset/ Complete Description | C23: Oty. | D23: Value at Cost ( ` In Lacs)
A24: PPF | B24: Refer Annexure - 2 | D24: ='Annexure-2 Movable Property'!I6 -> 0
A25: Pension Scheme | D25: ='Annexure-2 Movable Property'!I10 -> 0
A26: Investment in HUF | D26: ='Annexure-2 Movable Property'!I14 -> 0
A27: Shares | D27: ='Annexure-2 Movable Property'!I16 -> 0
A28: Fixed Deposit | D28: ='Annexure-2 Movable Property'!I23 -> 0
A29: Recurring Deposit | D29: ='Annexure-2 Movable Property'!I27 -> 0
A30: Other Deposit | D30: ='Annexure-2 Movable Property'!I31 -> 0
A31: Insurance Policies | D31: ='Annexure-2 Movable Property'!I35 -> 0
A32: Vehcile | D32: ='Annexure-2 Movable Property'!I45 -> 0
A33: Invesement in Firm , Companies | D33: ='Annexure-2 Movable Property'!I52 -> 0
A34: TOTAL (B) | D34: =SUM(D24:D33) -> 0
A35: (C) Total Liabilities:
A37: Borrowed From | B37: Amount & Securities offered | C37: Purpose | D37: O/s as on date ( ` In Lacs)
A38: ICICI | C38: Housing
A39: Deposit | C39: Rent
C40: Repayment of H. Loan
A41: TOTAL
A42: (D) Net Worth: (A + B – C) = /- Lacs
A43: (In words ___________________________________)
A44: He is the Guarantor for various Borrowings by his friends / relatives / firm(s) / company(s) as detailed below:
A46: Guaranteed to | B46: For the Borrowings by | C46: Purpose | D46: Amount Guaranteed ( ` In Lacs)
C47: Term Loan
C48: Vehicles
...

Sheet Annexure-1 Immovable Property
A4: (A) Total Value of Immoveable Property:
A5: (This includes beneficial share owned in Land, Building, Flat, Factory, Shop, House etc.)
J6: Source of Fund - Loan | P6: Source of Fund - Othres | U6: Total Source of Fund
A7: Nature of Property | B7: Location with Complete Address | C7: Date of Purchase | D7: Property Cost excluding Registration and Stamp Charges | E7: Registration Charges | F7: Stamp charges | G7: Vendor Name / Seller Name Address with PAN No ( if Available) | H7: Value at Cost ( ` In Lacs) | J7: Bank | K7: Loan Amt, Received | L7: Sanction Letter Ref. No ( if available) | M7: Date of loan Amount Received | N7: Outstanidng Loan Amount as on Net Worth Certificate | P7: Salary | Q7: withdrawal from SB A/c | R7: withdrawal from FD A/c | S7: Other Source | T7: Total of other source of income
A8: By Self | H8: =SUM(H9:H11) -> 0
A9: Flat at | B9: Sholinganallur | J9: ICICI Bank | P9: ICICI Bank | U9: =T9+K9 -> 0
A10: Shop | B10: -
A11: Shop | B11: -
A12: By Sharing | H12: =SUM(H13:H15) -> 0
A13: Flat at
A14: Shop | B14: -
A15: Shop | B15: -

Sheet Annexure-2 Movable Property
A2: (B) Total Value of Other Assets:
A3: (This includes Cash, Bank balance, Gold, Other Jewellery, Investment in Shares/Mutual Funds/FD’s/LIC etc, Vehicles, Capital in Business , HUF etc.)
K4: Source of Fund - Loan | Q4: Source of Fund - Othres | V4: Total Source of Fund
A5: Nature of Asset | B5: Reference No | C5: Held with | D5: Date of Investment | E5: Value at Cost ( ` In Lacs) | F5: Sold / withdrawan Amount | G5: Date of Sold / withdrawan | I5: Present Value ( in Lacs) | K5: Bank | L5: Loan Amt, Received | M5: Sanction Letter Ref. No ( if available) | N5: Date of loan Amount Received | O5: Outstanidng Loan Amount as on Net Worth Certificate | Q5: Salary | R5: withdrawal from SB A/c | S5: withdrawal from FD A/c | T5: Other Source | U5: Total of other source of income
A6: PPF | I6: =SUM(I7:I9) -> 0
A7: self
A8: Spouse
A9: Children
A10: Pension Scheme | I10: =SUM(I11:I13) -> 0 | V10: =U10+L10 -> 0
A11: self
A12: Spouse
A13: Children
A14: Investment in HUF | I14: =I15 -> 0
A15: Name of HUF
A16: Shares | I16: =SUM(I17:I22) -> 0
A17: Company 1
A18: Company 2
A19: Company 3
A20: Company 4
A21: Company 5
A22: Company 6
A23: Fixed Deposit | I23: =SUM(I24:I26) -> 0
A24: self
A25: Spouse
A26: Children
A27: Recurring Deposit | I27: =SUM(I28:I30) -> 0
A28: self
A29: Spouse
A30: Children
A31: Other Deposit (Specify) | I31: =SUM(I32:I34) -> 0
A32: self
A33: Spouse
A34: Children
A35: Insurance Policies | I35: =I36+I39+I42 -> 0
A36: self | I36: =SUM(I37:I38) -> 0
A37: Policy 1
A38: Policy 2
A39: Spouse | I39: =SUM(I40:I41) -> 0
A40: Policy 1
A41: Policy 2
...
